<?xml version="1.0"?>
<robot name="diff_robot2" xmlns:xacro="http://www.ros.org/wiki/xacro">

    <!-- 1. DEFINE MATERIALS (RViz) -->
    <material name="grey"><color rgba="0.7 0.7 0.7 1" /></material>
    <material name="black"><color rgba="0 0 0 1" /></material>
    <material name="white"><color rgba="1 1 1 1" /></material>

    <!-- 2. DEFINE PROPERTIES -->
    <xacro:property name="base_length" value="0.6"/>
    <xacro:property name="base_width" value="0.4"/>
    <xacro:property name="base_height" value="0.2"/>
    <xacro:property name="wheel_radius" value="0.1"/>
    <xacro:property name="wheel_length" value="0.05"/>
    <xacro:property name="wheel_x_offset" value="-0.15"/>
    <xacro:property name="wheel_y_offset" value="0.225"/>

    <!-- 3. INERTIAL MACROS -->
    <xacro:macro name="inertial_sphere" params="mass radius *origin">
        <inertial>
            <xacro:insert_block name="origin"/>
            <mass value="${mass}" />
            <inertia ixx="${(2/5) * mass * (radius*radius)}" ixy="0.0" ixz="0.0"
                     iyy="${(2/5) * mass * (radius*radius)}" iyz="0.0"
                     izz="${(2/5) * mass * (radius*radius)}" />
        </inertial>
    </xacro:macro>  

    <xacro:macro name="inertial_box" params="mass x y z *origin">
        <inertial>
            <xacro:insert_block name="origin"/>
            <mass value="${mass}" />
            <inertia ixx="${(1/12) * mass * (y*y+z*z)}" ixy="0.0" ixz="0.0"
                     iyy="${(1/12) * mass * (x*x+z*z)}" iyz="0.0"
                     izz="${(1/12) * mass * (x*x+y*y)}" />
        </inertial>
    </xacro:macro>

    <xacro:macro name="inertial_cylinder" params="mass length radius *origin">
        <inertial>
            <xacro:insert_block name="origin"/>
            <mass value="${mass}" />
            <inertia ixx="${(1/12) * mass * (3*radius*radius + length*length)}" ixy="0.0" ixz="0.0"
                     iyy="${(1/12) * mass * (3*radius*radius + length*length)}" iyz="0.0"
                     izz="${(1/2) * mass * (radius*radius)}" />
        </inertial>
    </xacro:macro>

    <!-- 4. BASE LINK -->
    <link name="base_footprint" />

    <joint name="base_joint" type="fixed">
        <parent link="base_footprint"/>
        <child link="base_link"/>
        <origin xyz="0 0 0.1" rpy="0 0 0"/>
    </joint>

    <link name="base_link">
        <visual>
            <geometry><box size="${base_length} ${base_width} ${base_height}" /></geometry>
            <origin xyz="0 0 ${base_height / 2}" rpy="0 0 0" />
            <material name="black"/>
        </visual>
        <collision>
            <geometry><box size="${base_length} ${base_width} ${base_height}" /></geometry>
            <origin xyz="0 0 ${base_height / 2}" rpy="0 0 0" />
        </collision>
        <xacro:inertial_box mass="10.0" x="${base_length}" y="${base_width}" z="${base_height}">
            <origin xyz="0 0 ${base_height / 2}" rpy="0 0 0" />
        </xacro:inertial_box>
    </link>

    <!-- 5. WHEEL MACRO -->
    <xacro:macro name="wheel" params="prefix y_reflect">
        <link name="${prefix}_wheel_link">
            <visual>
                <geometry><cylinder radius="${wheel_radius}" length="${wheel_length}" /></geometry>
                <origin xyz="0 0 0" rpy="${pi/2} 0 0" />
                <material name="grey"/>
            </visual>
            <collision>
                <geometry><cylinder radius="${wheel_radius}" length="${wheel_length}" /></geometry>
                <origin xyz="0 0 0" rpy="${pi/2} 0 0" />
            </collision>
            <xacro:inertial_cylinder mass="1.0" length="${wheel_length}" radius="${wheel_radius}">
                <origin xyz="0 0 0" rpy="${pi/2} 0 0" />
            </xacro:inertial_cylinder>
        </link>

        <joint name="base_to_${prefix}_wheel" type="continuous">
            <parent link="base_link"/>
            <child link="${prefix}_wheel_link"/>
            <origin xyz="${wheel_x_offset} ${y_reflect * wheel_y_offset} 0" rpy="0 0 0"/>
            <axis xyz="0 1 0"/>
        </joint>

        <gazebo reference="${prefix}_wheel_link">
            <mu1 value="1.0"/>
            <mu2 value="1.0"/>
        </gazebo>
    </xacro:macro>

    <xacro:wheel prefix="right" y_reflect="-1" />
    <xacro:wheel prefix="left" y_reflect="1" />

    <!-- 6. CASTER WHEEL -->
    <link name="caster_wheel_link">
        <visual>
            <geometry><sphere radius="${wheel_radius / 2}" /></geometry>
            <material name="grey"/>
        </visual>
        <collision>
            <geometry><sphere radius="${wheel_radius / 2}" /></geometry>
        </collision>
        <xacro:inertial_sphere mass="0.5" radius="${wheel_radius / 2}">
            <origin xyz="0 0 0" rpy="0 0 0" />
        </xacro:inertial_sphere>
    </link>

    <joint name="base_to_caster_wheel" type="fixed">
        <parent link="base_link"/>
        <child link="caster_wheel_link"/>
        <origin xyz="0.2 0 -0.05" rpy="0 0 0"/>
    </joint>

    <gazebo reference="caster_wheel_link">
        <mu1 value="0.001"/>
        <mu2 value="0.001"/>
    </gazebo>

    <!-- 7. LIDAR -->
    <link name="Lidar_link">
        <visual>
            <geometry><cylinder radius="0.1" length="0.05" /></geometry>
            <material name="white"/>
        </visual>
        <collision>
            <geometry><cylinder radius="0.1" length="0.05" /></geometry>
        </collision>
        <xacro:inertial_cylinder mass="0.2" length="0.05" radius="0.1">
            <origin xyz="0 0 0" rpy="0 0 0" />
        </xacro:inertial_cylinder>
    </link>

    <joint name="base_to_lidar" type="fixed">
        <parent link="base_link"/>
        <child link="Lidar_link"/>
        <origin xyz="0 0 0.225" rpy="0 0 0"/>
    </joint>

    <!-- 8. GAZEBO PLUGINS (GZ SIM / IGNITION) -->
    <gazebo>
        <!-- Differential Drive Plugin -->
        <plugin filename="gz-sim-diff-drive-system" name="gz::sim::systems::DiffDrive">
            <left_joint>base_to_left_wheel</left_joint>
            <right_joint>base_to_right_wheel</right_joint>
            <wheel_separation>${2 * wheel_y_offset}</wheel_separation>
            <wheel_radius>${wheel_radius}</wheel_radius>
            
            <topic>cmd_vel</topic>
            
            <odom_topic>odom</odom_topic>
            <frame_id>odom</frame_id>
            <child_frame_id>base_footprint</child_frame_id>
            <odom_publisher_frequency>30</odom_publisher_frequency>
            
            <tf_topic>/tf</tf_topic>
        </plugin>

        <!-- sensor plugin-->
        <plugin filename="gz-sim-sensors-system" name="gz::sim::systems::Sensors">
            <render_engine>ogre2</render_engine>
        </plugin>

        <!-- Joint State Publisher Plugin -->
        <plugin filename="gz-sim-joint-state-publisher-system" name="gz::sim::systems::JointStatePublisher">
            <topic>joint_states</topic>
            <joint_name>base_to_left_wheel</joint_name>
            <joint_name>base_to_right_wheel</joint_name>
        </plugin>
    </gazebo>

    <!-- LIDAR SENSOR LASER-->
    <gazebo reference="Lidar_link">
        <sensor name="lidar" type="gpu_lidar">
            <always_on>true</always_on>
            <visualize>true</visualize>
            <update_rate>10</update_rate>
            <topic>scan</topic>
            <gz_frame_id>Lidar_link</gz_frame_id>
            <ray>
                <scan>
                    <horizontal>
                        <samples>360</samples>
                        <resolution>1.000000</resolution>
                        <min_angle>-3.14159</min_angle>
                        <max_angle>3.14159</max_angle>
                    </horizontal>
                </scan>
                <range>
                    <min>0.120000</min>
                    <max>10.0</max>
                    <resolution>0.015000</resolution>
                </range>
                <noise>
                    <type>gaussian</type>
                    <mean>0.0</mean>
                    <stddev>0.01</stddev>
                </noise>
            </ray>
        </sensor>
    </gazebo>

    <link name="camera_link">
        <visual>
            <geometry><box size="0.05 0.1 0.05" /></geometry>
            <material name="black"/>
        </visual>
        <collision>
            <geometry><box size="0.05 0.1 0.05" /></geometry>
        </collision>
        <xacro:inertial_box mass="0.1" x="0.05" y="0.1" z="0.05">
            <origin xyz="0 0 0" rpy="0 0 0" />
        </xacro:inertial_box>
    </link>

    <joint name="base_to_camera" type="fixed">
        <parent link="base_link"/>
        <child link="camera_link"/>
        <origin xyz="${base_length / 2} 0 0.15" rpy="0 0 0"/>
    </joint>

    <gazebo reference="camera_link">
        <sensor name="camera_sensor" type="camera">
            <always_on>1</always_on>
            <update_rate>30</update_rate>
            <visualize>true</visualize>
            <topic>camera/image_raw</topic>
            <gz_frame_id>camera_link</gz_frame_id>
            <camera>
                <horizontal_fov>1.047</horizontal_fov>
                <image>
                    <width>640</width>
                    <height>480</height>
                </image>
                <clip>
                    <near>0.1</near>
                    <far>100</far>
                </clip>
            </camera>
        </sensor>
    </gazebo>

</robot>