<?xml version="1.0"?>
<robot name="diff_robot2" xmlns:xacro="http://www.ros.org/wiki/xacro">

    <!-- 1. DEFINE MATERIALS (RViz) -->
    <material name="grey"><color rgba="0.7 0.7 0.7 1" /></material>
    <material name="black"><color rgba="0 0 0 1" /></material>
    <material name="white"><color rgba="1 1 1 1" /></material>

    <!-- 2. DEFINE PROPERTIES -->
    <xacro:property name="base_length" value="0.6"/>
    <xacro:property name="base_width" value="0.4"/>
    <xacro:property name="base_height" value="0.2"/>
    <xacro:property name="wheel_radius" value="0.1"/>
    <xacro:property name="wheel_length" value="0.05"/>
    <xacro:property name="wheel_x_offset" value="-0.15"/>
    <xacro:property name="wheel_y_offset" value="0.225"/>

    <!-- 3. INERTIAL MACROS -->
    <xacro:macro name="inertial_sphere" params="mass radius *origin">
        <inertial>
            <xacro:insert_block name="origin"/>
            <mass value="${mass}" />
            <inertia ixx="${(2/5) * mass * (radius*radius)}" ixy="0.0" ixz="0.0"
                     iyy="${(2/5) * mass * (radius*radius)}" iyz="0.0"
                     izz="${(2/5) * mass * (radius*radius)}" />
        </inertial>
    </xacro:macro>  

    <xacro:macro name="inertial_box" params="mass x y z *origin">
        <inertial>
            <xacro:insert_block name="origin"/>
            <mass value="${mass}" />
            <inertia ixx="${(1/12) * mass * (y*y+z*z)}" ixy="0.0" ixz="0.0"
                     iyy="${(1/12) * mass * (x*x+z*z)}" iyz="0.0"
                     izz="${(1/12) * mass * (x*x+y*y)}" />
        </inertial>
    </xacro:macro>

    <xacro:macro name="inertial_cylinder" params="mass length radius *origin">
        <inertial>
            <xacro:insert_block name="origin"/>
            <mass value="${mass}" />
            <inertia ixx="${(1/12) * mass * (3*radius*radius + length*length)}" ixy="0.0" ixz="0.0"
                     iyy="${(1/12) * mass * (3*radius*radius + length*length)}" iyz="0.0"
                     izz="${(1/2) * mass * (radius*radius)}" />
        </inertial>
    </xacro:macro>

    <!-- 4. BASE LINK -->
    <link name="base_footprint_link" />

    <joint name="base_joint" type="fixed">
        <parent link="base_footprint_link"/>
        <child link="base_link"/>
        <origin xyz="0 0 0.1" rpy="0 0 0"/>
    </joint>

    <link name="base_link">
        <visual>
            <geometry><box size="${base_length} ${base_width} ${base_height}" /></geometry>
            <origin xyz="0 0 ${base_height / 2}" rpy="0 0 0" />
            <material name="black"/>
        </visual>
        <collision>
            <geometry><box size="${base_length} ${base_width} ${base_height}" /></geometry>
            <origin xyz="0 0 ${base_height / 2}" rpy="0 0 0" />
        </collision>
        <xacro:inertial_box mass="10.0" x="${base_length}" y="${base_width}" z="${base_height}">
            <origin xyz="0 0 ${base_height / 2}" rpy="0 0 0" />
        </xacro:inertial_box>
    </link>

    <!-- 5. WHEEL MACRO -->
    <xacro:macro name="wheel" params="prefix y_reflect">
        <link name="${prefix}_wheel_link">
            <visual>
                <geometry><cylinder radius="${wheel_radius}" length="${wheel_length}" /></geometry>
                <origin xyz="0 0 0" rpy="${pi/2} 0 0" />
                <material name="grey"/>
            </visual>
            <collision>
                <geometry><cylinder radius="${wheel_radius}" length="${wheel_length}" /></geometry>
                <origin xyz="0 0 0" rpy="${pi/2} 0 0" />
            </collision>
            <xacro:inertial_cylinder mass="1.0" length="${wheel_length}" radius="${wheel_radius}">
                <origin xyz="0 0 0" rpy="${pi/2} 0 0" />
            </xacro:inertial_cylinder>
        </link>
        <joint name="base_to_${prefix}_wheel" type="continuous">
            <parent link="base_link"/>
            <child link="${prefix}_wheel_link"/>
            <origin xyz="${wheel_x_offset} ${y_reflect * wheel_y_offset} 0" rpy="0 0 0"/>
            <axis xyz="0 1 0"/>
        </joint>
    </xacro:macro>

    <xacro:wheel prefix="right" y_reflect="-1" />
    <xacro:wheel prefix="left" y_reflect="1" />

    <!-- 6. CASTER WHEEL -->
    <link name="caster_wheel_link">
        <visual>
            <geometry><sphere radius="${wheel_radius / 2}" /></geometry>
            <material name="grey"/>
        </visual>
        <collision>
            <geometry><sphere radius="${wheel_radius / 2}" /></geometry>
        </collision>
        <xacro:inertial_sphere mass="0.5" radius="${wheel_radius / 2}">
            <origin xyz="0 0 0" rpy="0 0 0" />
        </xacro:inertial_sphere>
    </link>

    <joint name="base_to_caster_wheel" type="fixed">
        <parent link="base_link"/>
        <child link="caster_wheel_link"/>
        <origin xyz="0.2 0 -0.05" rpy="0 0 0"/>
    </joint>

    <!-- 7. LIDAR -->
    <link name="Lidar_link">
        <visual>
            <geometry><cylinder radius="0.1" length="0.05" /></geometry>
            <material name="white"/>
        </visual>
        <collision>
            <geometry><cylinder radius="0.1" length="0.05" /></geometry>
        </collision>
        <xacro:inertial_cylinder mass="0.2" length="0.05" radius="0.1">
            <origin xyz="0 0 0" rpy="0 0 0" />
        </xacro:inertial_cylinder>
    </link>

    <joint name="base_to_lidar" type="fixed">
        <parent link="base_link"/>
        <child link="Lidar_link"/>
        <origin xyz="0 0 0.225" rpy="0 0 0"/>
    </joint>

    <!-- 8. GAZEBO PLUGINS & PHYSICS -->
    <gazebo reference="base_link">
        <material>Gazebo/Black</material>
    </gazebo>
    <gazebo reference="right_wheel_link">
        <material>Gazebo/Grey</material>
        <mu1 value="0.2"/><mu2 value="0.2"/> <!-- Traction -->
    </gazebo>
    <gazebo reference="left_wheel_link">
        <material>Gazebo/Grey</material>
        <mu1 value="0.2"/><mu2 value="0.2"/>
    </gazebo>
    <gazebo reference="caster_wheel_link">
        <material>Gazebo/Grey</material>
        <mu1 value="0.0002"/><mu2 value="0.0002"/> <!-- Low friction to slide -->
    </gazebo>

</robot>